Workbook

Sheet Assets
B3: Paleta de Cores
B5: # 9BC848 | C5: Xbox Color | E5: # E8E6E9 | F5: negative zone
B6: # 22C55E | C6: Xbox Color
B7: # 2AE6B1 | C7: Menus
B8: # 5BF6A8 | C8: Menus
B12: Logos | J12: ícones

Sheet Base
A1: Subscriber ID | B1: Name | C1: Plan | D1: Start Date | E1: Auto Renewal | F1: Subscription Price | G1: Subscription Type | H1: EA Play Season Pass | I1: EA Play Season Pass Price | J1: Minecraft Season Pass | K1: Minecraft Season Pass Price | L1: Coupon Value | M1: Total Value
A2: 3231 | B2: João Silva | C2: Ultimate | D2: 45292 | E2: Yes | F2: 15 | G2: Monthly | H2: Yes | I2: 30 | J2: Yes | K2: 20 | L2: 5 | M2: 60
A3: 3232 | B3: Maria Oliveira | C3: Core | D3: 45306 | E3: No | F3: 5 | G3: Annual | H3: No | I3: - | J3: No | K3: 0 | L3: 0 | M3: 5
A4: 3233 | B4: Lucas Fernandes | C4: Standard | D4: 45332 | E4: Yes | F4: 10 | G4: Quarterly | H4: No | I4: - | J4: Yes | K4: 20 | L4: 10 | M4: 20
A5: 3234 | B5: Ana Souza | C5: Ultimate | D5: 45342 | E5: No | F5: 15 | G5: Monthly | H5: Yes | I5: 30 | J5: Yes | K5: 20 | L5: 3 | M5: 62
A6: 3235 | B6: Pedro Gonçalves | C6: Core | D6: 45356 | E6: Yes | F6: 5 | G6: Monthly | H6: No | I6: - | J6: No | K6: 0 | L6: 1 | M6: 4
A7: 3236 | B7: Felipe Costa | C7: Standard | D7: 45353 | E7: No | F7: 10 | G7: Monthly | H7: No | I7: - | J7: Yes | K7: 20 | L7: 2 | M7: 28
A8: 3237 | B8: Camila Ribeiro | C8: Ultimate | D8: 45354 | E8: Yes | F8: 15 | G8: Quarterly | H8: Yes | I8: 30 | J8: Yes | K8: 20 | L8: 10 | M8: 55
A9: 3238 | B9: André Mendes | C9: Core | D9: 45355 | E9: Yes | F9: 5 | G9: Annual | H9: No | I9: - | J9: No | K9: 0 | L9: 0 | M9: 5
A10: 3239 | B10: Sofia Almeida | C10: Ultimate | D10: 45356 | E10: No | F10: 15 | G10: Monthly | H10: Yes | I10: 30 | J10: Yes | K10: 20 | L10: 5 | M10: 60
A11: 3240 | B11: Bruno Martins | C11: Standard | D11: 45357 | E11: Yes | F11: 10 | G11: Quarterly | H11: No | I11: - | J11: Yes | K11: 20 | L11: 15 | M11: 15
A12: 3241 | B12: Rita Castro | C12: Core | D12: 45358 | E12: No | F12: 5 | G12: Monthly | H12: No | I12: - | J12: No | K12: 0 | L12: 1 | M12: 4
A13: 3242 | B13: Marco Túlio | C13: Ultimate | D13: 45359 | E13: Yes | F13: 15 | G13: Annual | H13: Yes | I13: 30 | J13: Yes | K13: 20 | L13: 20 | M13: 45
A14: 3243 | B14: Lívia Silveira | C14: Standard | D14: 45360 | E14: No | F14: 10 | G14: Monthly | H14: No | I14: - | J14: Yes | K14: 20 | L14: 10 | M14: 20
A15: 3244 | B15: Diogo Sousa | C15: Core | D15: 45361 | E15: Yes | F15: 5 | G15: Quarterly | H15: No | I15: - | J15: No | K15: 0 | L15: 0 | M15: 5
A16: 3245 | B16: Fernanda Lima | C16: Ultimate | D16: 45362 | E16: No | F16: 15 | G16: Monthly | H16: Yes | I16: 30 | J16: Yes | K16: 20 | L16: 8 | M16: 57
A17: 3246 | B17: Caio Pereira | C17: Standard | D17: 45363 | E17: Yes | F17: 10 | G17: Annual | H17: No | I17: - | J17: Yes | K17: 20 | L17: 12 | M17: 18
A18: 3247 | B18: Beatriz Gomes | C18: Core | D18: 45364 | E18: No | F18: 5 | G18: Monthly | H18: No | I18: - | J18: No | K18: 0 | L18: 2 | M18: 3
A19: 3248 | B19: Cesar Oliveira | C19: Ultimate | D19: 45365 | E19: Yes | F19: 15 | G19: Quarterly | H19: Yes | I19: 30 | J19: Yes | K19: 20 | L19: 7 | M19: 58
A20: 3249 | B20: Débora Machado | C20: Standard | D20: 45366 | E20: No | F20: 10 | G20: Monthly | H20: No | I20: - | J20: Yes | K20: 20 | L20: 5 | M20: 25
A21: 3250 | B21: Eduardo Vargas | C21: Core | D21: 45367 | E21: Yes | F21: 5 | G21: Annual | H21: No | I21: - | J21: No | K21: 0 | L21: 0 | M21: 5
A22: 3251 | B22: Gabriela Santos | C22: Ultimate | D22: 45368 | E22: No | F22: 15 | G22: Monthly | H22: Yes | I22: 30 | J22: Yes | K22: 20 | L22: 3 | M22: 62
A23: 3252 | B23: Henrique Dias | C23: Standard | D23: 45369 | E23: Yes | F23: 10 | G23: Quarterly | H23: No | I23: - | J23: Yes | K23: 20 | L23: 15 | M23: 15
A24: 3253 | B24: Isabela Moreira | C24: Core | D24: 45370 | E24: No | F24: 5 | G24: Monthly | H24: No | I24: - | J24: No | K24: 0 | L24: 1 | M24: 4
A25: 3254 | B25: Joaquim Barbosa | C25: Ultimate | D25: 45371 | E25: Yes | F25: 15 | G25: Annual | H25: Yes | I25: 30 | J25: Yes | K25: 20 | L25: 20 | M25: 45
A26: 3255 | B26: Lara Rocha | C26: Standard | D26: 45372 | E26: No | F26: 10 | G26: Monthly | H26: No | I26: - | J26: Yes | K26: 20 | L26: 10 | M26: 20
A27: 3256 | B27: Matheus Silva | C27: Core | D27: 45373 | E27: Yes | F27: 5 | G27: Quarterly | H27: No | I27: - | J27: No | K27: 0 | L27: 0 | M27: 5
A28: 3257 | B28: Nicole Costa | C28: Ultimate | D28: 45374 | E28: No | F28: 15 | G28: Monthly | H28: Yes | I28: 30 | J28: Yes | K28: 20 | L28: 5 | M28: 60
A29: 3258 | B29: Otávio Mendonça | C29: Standard | D29: 45375 | E29: Yes | F29: 10 | G29: Annual | H29: No | I29: - | J29: Yes | K29: 20 | L29: 15 | M29: 15
A30: 3259 | B30: Paula Ferreira | C30: Core | D30: 45376 | E30: No | F30: 5 | G30: Monthly | H30: No | I30: - | J30: No | K30: 0 | L30: 1 | M30: 4
A31: 3260 | B31: Raquel Alves | C31: Ultimate | D31: 45377 | E31: Yes | F31: 15 | G31: Quarterly | H31: Yes | I31: 30 | J31: Yes | K31: 20 | L31: 7 | M31: 58
A32: 3261 | B32: Samuel Pires | C32: Standard | D32: 45378 | E32: No | F32: 10 | G32: Monthly | H32: No | I32: - | J32: Yes | K32: 20 | L32: 10 | M32: 20
A33: 3262 | B33: Tânia Barros | C33: Core | D33: 45379 | E33: Yes | F33: 5 | G33: Annual | H33: No | I33: - | J33: No | K33: 0 | L33: 0 | M33: 5
A34: 3263 | B34: Vinicius Lima | C34: Ultimate | D34: 45380 | E34: No | F34: 15 | G34: Monthly | H34: Yes | I34: 30 | J34: Yes | K34: 20 | L34: 3 | M34: 62
A35: 3264 | B35: Yasmin Teixeira | C35: Standard | D35: 45381 | E35: Yes | F35: 10 | G35: Quarterly | H35: No | I35: - | J35: Yes | K35: 20 | L35: 15 | M35: 15
A36: 3265 | B36: Zé Carlos | C36: Core | D36: 45382 | E36: No | F36: 5 | G36: Monthly | H36: No | I36: - | J36: No | K36: 0 | L36: 1 | M36: 4
A37: 3266 | B37: Amanda Nogueira | C37: Core | D37: 45383 | E37: Yes | F37: 5 | G37: Monthly | H37: No | I37: - | J37: No | K37: 0 | L37: 0 | M37: 5
A38: 3267 | B38: Bruno Cavalheiro | C38: Ultimate | D38: 45384 | E38: No | F38: 15 | G38: Quarterly | H38: Yes | I38: 30 | J38: Yes | K38: 20 | L38: 7 | M38: 58
A39: 3268 | B39: Carla Dias | C39: Standard | D39: 45385 | E39: Yes | F39: 10 | G39: Annual | H39: No | I39: - | J39: Yes | K39: 20 | L39: 10 | M39: 20
A40: 3269 | B40: Diego Fontes | C40: Core | D40: 45386 | E40: No | F40: 5 | G40: Quarterly | H40: No | I40: - | J40: No | K40: 0 | L40: 1 | M40: 4
...

Sheet Calculos
A1: Mês | B1: Receita Mensal | D1: Plano | E1: Receita por Plano | G1: Tipo | H1: Receita por Tipo | J1: Renovação | K1: Qtde | L1: Receita | N1: KPI | O1: Valor | Q1: Rank | R1: Cliente | S1: Receita
A2: 45292 | B2: =SUMIFS(Base!$M$2:$M$296,Base!$D$2:$D$296,">="&A2,Base!$D$2:$D$296,"<"&EDATE(A2,1)) | D2: Ultimate | E2: =SUMIF(Base!$C$2:$C$296,D2,Base!$M$2:$M$296) | G2: Monthly | H2: =SUMIF(Base!$G$2:$G$296,G2,Base!$M$2:$M$296) | J2: Yes | K2: =COUNTIF(Base!$E$2:$E$296,J2) | L2: =SUMIF(Base!$E$2:$E$296,J2,Base!$M$2:$M$296) | N2: Receita Total | O2: =SUM(B2:B13) | Q2: 1 | R2: Joana Silveira | S2: 120
A3: 45323 | B3: =SUMIFS(Base!$M$2:$M$296,Base!$D$2:$D$296,">="&A3,Base!$D$2:$D$296,"<"&EDATE(A3,1)) | D3: Standard | E3: =SUMIF(Base!$C$2:$C$296,D3,Base!$M$2:$M$296) | G3: Quarterly | H3: =SUMIF(Base!$G$2:$G$296,G3,Base!$M$2:$M$296) | J3: No | K3: =COUNTIF(Base!$E$2:$E$296,J3) | L3: =SUMIF(Base!$E$2:$E$296,J3,Base!$M$2:$M$296) | N3: Ticket Médio | O3: =AVERAGE(Base!$M$2:$M$296) | Q3: 2 | R3: Geraldo Ribeiro | S3: 107
A4: 45352 | B4: =SUMIFS(Base!$M$2:$M$296,Base!$D$2:$D$296,">="&A4,Base!$D$2:$D$296,"<"&EDATE(A4,1)) | D4: Core | E4: =SUMIF(Base!$C$2:$C$296,D4,Base!$M$2:$M$296) | G4: Annual | H4: =SUMIF(Base!$G$2:$G$296,G4,Base!$M$2:$M$296) | N4: % Auto Renewal | O4: =COUNTIF(Base!$E$2:$E$296,"Yes")/COUNTA(Base!$E$2:$E$296) | Q4: 3 | R4: Daniela Moura | S4: 105
A5: 45383 | B5: =SUMIFS(Base!$M$2:$M$296,Base!$D$2:$D$296,">="&A5,Base!$D$2:$D$296,"<"&EDATE(A5,1)) | N5: Assinantes | O5: =COUNTA(Base!$A$2:$A$296) | Q5: 4 | R5: Kléber Oliveira | S5: 80
A6: 45413 | B6: =SUMIFS(Base!$M$2:$M$296,Base!$D$2:$D$296,">="&A6,Base!$D$2:$D$296,"<"&EDATE(A6,1)) | Q6: 5 | R6: Xuxa Meneghel | S6: 70
A7: 45444 | B7: =SUMIFS(Base!$M$2:$M$296,Base!$D$2:$D$296,">="&A7,Base!$D$2:$D$296,"<"&EDATE(A7,1)) | Q7: 6 | R7: Elisa Neves | S7: 67
A8: 45474 | B8: =SUMIFS(Base!$M$2:$M$296,Base!$D$2:$D$296,">="&A8,Base!$D$2:$D$296,"<"&EDATE(A8,1)) | Q8: 7 | R8: Raquel Novaes | S8: 62
A9: 45505 | B9: =SUMIFS(Base!$M$2:$M$296,Base!$D$2:$D$296,">="&A9,Base!$D$2:$D$296,"<"&EDATE(A9,1)) | Q9: 8 | R9: Gabriel Santos | S9: 62
A10: 45536 | B10: =SUMIFS(Base!$M$2:$M$296,Base!$D$2:$D$296,">="&A10,Base!$D$2:$D$296,"<"&EDATE(A10,1)) | Q10: 9 | R10: Patrícia Leite | S10: 62
A11: 45566 | B11: =SUMIFS(Base!$M$2:$M$296,Base!$D$2:$D$296,">="&A11,Base!$D$2:$D$296,"<"&EDATE(A11,1)) | Q11: 10 | R11: Elisa Correia | S11: 62
A12: 45597 | B12: =SUMIFS(Base!$M$2:$M$296,Base!$D$2:$D$296,">="&A12,Base!$D$2:$D$296,"<"&EDATE(A12,1))
A13: 45627 | B13: =SUMIFS(Base!$M$2:$M$296,Base!$D$2:$D$296,">="&A13,Base!$D$2:$D$296,"<"&EDATE(A13,1))

Sheet Dashboard
A1: Dashboard de Vendas - Xbox Game Pass
A3: Visão geral da base de assinaturas de 2024 com foco em receita, perfil de compra e clientes de maior valor
A5: Receita Total | D5: Ticket Médio | G5: % Auto Renewal | J5: Assinantes
A6: =Calculos!O2 | D6: =Calculos!O3 | G6: =Calculos!O4 | J6: =Calculos!O5
A9: Receita por Plano | G9: Receita Mensal
A20: Legenda: receita total por plano. | G20: Legenda: evolução mensal da receita em 2024.
A22: Receita por Tipo de Assinatura | G22: Renovação Automática
A33: Legenda: comparação entre planos mensal, trimestral e anual. | G33: Legenda: participação de clientes com e sem renovação automática.
A35: Top 10 Clientes por Receita (agregado por cliente)
A36: Rank | B36: Cliente | C36: Receita
A37: 1 | B37: Joana Silveira | C37: 120
A38: 2 | B38: Geraldo Ribeiro | C38: 107
A39: 3 | B39: Daniela Moura | C39: 105
A40: 4 | B40: Kléber Oliveira | C40: 80
A41: 5 | B41: Xuxa Meneghel | C41: 70
A42: 6 | B42: Elisa Neves | C42: 67
A43: 7 | B43: Raquel Novaes | C43: 62
A44: 8 | B44: Gabriel Santos | C44: 62
A45: 9 | B45: Patrícia Leite | C45: 62
A46: 10 | B46: Elisa Correia | C46: 62
A47: Verificação feita: o ranking de clientes foi consolidado por nome, corrigindo a repetição indevida de um único cliente.
